<?xml version="1.0"?>
<robot name="mybot" xmlns:xacro="http://www.ros.org/wiki/xacro">

  <!-- Base Link -->
  <link name="base_link">
    <sensor name='gpu_lidar' type='gpu_lidar'>
        
        <topic>lidar</topic>
        <update_rate>10</update_rate>
        <ray>
            <scan>
                <horizontal>
                    <samples>640</samples>
                    <resolution>1</resolution>
                    <min_angle>-1.396263</min_angle>
                    <max_angle>1.396263</max_angle>
                </horizontal>
                <vertical>
                    <samples>1</samples>
                    <resolution>0.01</resolution>
                    <min_angle>0</min_angle>
                    <max_angle>0</max_angle>
                </vertical>
            </scan>
            <range>
                <min>0.08</min>
                <max>10.0</max>
                <resolution>0.01</resolution>
            </range>
        </ray>
        <always_on>1</always_on>
        <visualize>true</visualize>
    </sensor>
    <visual>
      <geometry>
        <box size="0.2 0.2 0.1"/>
      </geometry>
    </visual>
    <collision>
      <geometry>
        <box size="0.2 0.2 0.1"/>
      </geometry>
    </collision>
    <inertial>
      <mass value="1.0"/>
      <inertia ixx="0.00417" iyy="0.00417" izz="0.00667" ixy="0" ixz="0" iyz="0"/>
    </inertial>
  </link>

  <!-- Left Wheel -->
  <link name="left_wheel">
    <visual>
      <geometry>
        <cylinder length="0.02" radius="0.065"/>
      </geometry>
    </visual>
    <collision>
      <geometry>
        <cylinder length="0.02" radius="0.065"/>
      </geometry>
    </collision>
    <inertial>
      <mass value="0.1"/>
      <inertia ixx="0.000109" iyy="0.000211" izz="0.000109" ixy="0" ixz="0" iyz="0"/>
    </inertial>
  </link>

  <!-- Right Wheel -->
  <link name="right_wheel">
    <visual>
      <geometry>
        <cylinder length="0.02" radius="0.065"/>
      </geometry>
    </visual>
    <collision>
      <geometry>
        <cylinder length="0.02" radius="0.065"/>
      </geometry>
    </collision>
    <inertial>
      <mass value="0.1"/>
      <inertia ixx="0.000109" iyy="0.000211" izz="0.000109" ixy="0" ixz="0" iyz="0"/>
    </inertial>
  </link>

  <!-- Caster Wheel -->
  <link name="caster_wheel">
    <visual>
      <geometry>
        <sphere radius="0.021"/>
      </geometry>
      <material name="grey"/>
    </visual>
    <collision>
      <geometry>
        <sphere radius="0.03"/>
      </geometry>
    </collision>
    <inertial>
      <mass value="0.3"/>
      <inertia ixx="0.000108" iyy="0.000108" izz="0.000108" ixy="0" ixz="0" iyz="0"/>
    </inertial>
  </link>

  <!-- Hidden Lidar -->
  <link name="lidar_link">
    <inertial>
      <mass value="0.1"/>
      <inertia ixx="0.0001" iyy="0.0001" izz="0.0001" ixy="0" ixz="0" iyz="0"/>
    </inertial>
  </link>

  <joint name="lidar_joint" type="fixed">
    <parent link="base_link"/>
    <child link="lidar_link"/>
    <origin xyz="0 0 0.1" rpy="0 0 0"/>
  </joint>

  <!-- Hidden Camera -->
  <link name="camera_link">
    <inertial>
      <mass value="0.1"/>
      <inertia ixx="0.0001" iyy="0.0001" izz="0.0001" ixy="0" ixz="0" iyz="0"/>
    </inertial>
  </link>

  <joint name="camera_joint" type="fixed">
    <parent link="base_link"/>
    <child link="camera_link"/>
    <origin xyz="0 0 0.15" rpy="0 0 0"/>
  </joint>

  <!-- Joints -->
  <joint name="left_wheel_joint" type="continuous">
    <parent link="base_link"/>
    <child link="left_wheel"/>
    <origin xyz="-0.035 0.11 -0.015" rpy="1.57 0 0"/>
    <axis xyz="0 0 1"/>
  </joint>

  <joint name="right_wheel_joint" type="continuous">
    <parent link="base_link"/>
    <child link="right_wheel"/>
    <origin xyz="-0.035 -0.11 -0.015" rpy="1.57 0 0"/>
    <axis xyz="0 0 1"/>
  </joint>

  <joint name="caster_wheel_joint" type="continuous">
    <parent link="base_link"/>
    <child link="caster_wheel"/>
    <origin xyz="0.061 0.0 -0.05" rpy="0 0 0"/>
    <axis xyz="1 1 1"/>
  </joint>
  <frame name="lidar_frame" attached_to='base_link'>
    <pose>0.0 0 0.0 0 0 0</pose>
  </frame>

  <!-- Plugins -->
  <gazebo>
    <plugin filename="gz-sim-diff-drive-system" name="gz::sim::systems::DiffDrive">
      <left_joint>right_wheel_joint</left_joint>
      <right_joint>left_wheel_joint</right_joint>
      <wheel_separation>0.22</wheel_separation>
      <wheel_radius>0.065</wheel_radius>
      <odom_publish_frequency>30</odom_publish_frequency>
      <topic>cmd_vel</topic>
    </plugin>
  </gazebo>
  <gazebo>
    <plugin
      filename="gz-sim-sensors-system"
      name="gz::sim::systems::Sensors">
      <render_engine>ogre2</render_engine>
    </plugin>
  </gazebo>

  
  


</robot>
